Workbook

Sheet قاعدة بيانات المهام
A1: قاعدة بيانات المهام – مركز التنفيذ الاستراتيجي
A2: # | B2: المهمة | C2: القسم | D2: الموظف | E2: الأولوية | F2: الركيزة الاستراتيجية | G2: الحالة | H2: نسبة الإنجاز | I2: تاريخ البداية | J2: تاريخ الانتهاء | K2: الأيام المتبقية | L2: مؤشر المخاطر | M2: الملاحظات | N2: الخطوة القادمة | O2: ملاحظات الرئيس التنفيذي | P2: الشهر المصدر
A3: 1 | B3: إضافة توقيع الرئيس في الغرفة التجارية | C3: الموارد البشرية | G3: مكتملة | H3: 1 | I3: 45532 | J3: 45538 | K3: =IFERROR(IF(J3="","",IF(G3="مكتملة","✓",J3-TODAY())),"تاريخ غير صحيح") -> ✓ | L3: =IF(G3="مكتملة","🟢 مكتملة",IF(G3="لم تبدأ","⚪ لم تبدأ",IF(J3<TODAY(),"🔴 متأخرة",IF(AND(I3<>"",J3<>"",H3<>"",((TODAY()-I3)/(J3-I3)-H3)>0.3),"🟡 تحتاج متابعة","🟢 في المسار")))) -> 🟢 مكتملة | M3: باقي 3 تم انهاء 5 | N3: وليد العتيبي | P3: September
A4: 2 | B4: اتفاقية فصل إيرادات شريط المرقب واسواق المرقب | C4: الادارة القانونية | G4: مكتملة | H4: 1 | I4: 45544 | J4: 45551 | K4: =IFERROR(IF(J4="","",IF(G4="مكتملة","✓",J4-TODAY())),"تاريخ غير صحيح") -> ✓ | L4: =IF(G4="مكتملة","🟢 مكتملة",IF(G4="لم تبدأ","⚪ لم تبدأ",IF(J4<TODAY(),"🔴 متأخرة",IF(AND(I4<>"",J4<>"",H4<>"",((TODAY()-I4)/(J4-I4)-H4)>0.3),"🟡 تحتاج متابعة","🟢 في المسار")))) -> 🟢 مكتملة | M4: تم ارسال مسودة | N4: تم الارسال للأصول العقارية | P4: September
A5: 3 | B5: ارض الخزامى | C5: الاستثمار | G5: جاري العمل | H5: 0.9 | K5: =IFERROR(IF(J5="","",IF(G5="مكتملة","✓",J5-TODAY())),"تاريخ غير صحيح") | L5: =IF(G5="مكتملة","🟢 مكتملة",IF(G5="لم تبدأ","⚪ لم تبدأ",IF(J5<TODAY(),"🔴 متأخرة",IF(AND(I5<>"",J5<>"",H5<>"",((TODAY()-I5)/(J5-I5)-H5)>0.3),"🟡 تحتاج متابعة","🟢 في المسار")))) -> 🔴 متأخرة | M5: تم ارسال العقود للرئيس للتوقيع | N5: الرئيس التنفيذي | P5: September
A6: 4 | B6: استراتيجية الاستثمار | C6: الاستثمار | G6: جاري العمل | H6: 0.95 | I6: 45537 | J6: 45566 | K6: =IFERROR(IF(J6="","",IF(G6="مكتملة","✓",J6-TODAY())),"تاريخ غير صحيح") -> -548 | L6: =IF(G6="مكتملة","🟢 مكتملة",IF(G6="لم تبدأ","⚪ لم تبدأ",IF(J6<TODAY(),"🔴 متأخرة",IF(AND(I6<>"",J6<>"",H6<>"",((TODAY()-I6)/(J6-I6)-H6)>0.3),"🟡 تحتاج متابعة","🟢 في المسار")))) -> 🔴 متأخرة | M6: تم ارسال المسودة للرئيس التنفيذي | N6: الرئيس التنفيذي | P6: September
A7: 5 | B7: استشارة المراجع الخارجي في وجوب تقرير من مستشار مستقل بخصوص IFRS | C7: المالية | G7: مكتملة | H7: 1 | I7: 45522 | J7: 45533 | K7: =IFERROR(IF(J7="","",IF(G7="مكتملة","✓",J7-TODAY())),"تاريخ غير صحيح") -> ✓ | L7: =IF(G7="مكتملة","🟢 مكتملة",IF(G7="لم تبدأ","⚪ لم تبدأ",IF(J7<TODAY(),"🔴 متأخرة",IF(AND(I7<>"",J7<>"",H7<>"",((TODAY()-I7)/(J7-I7)-H7)>0.3),"🟡 تحتاج متابعة","🟢 في المسار")))) -> 🟢 مكتملة | M7: لا يوجد متطلب في المعايير الدولية لتعيين مستشار مستقل | N7: المدير المالي - للتحديث | P7: September
A8: 6 | B8: استلام محلات وشقق سوق ينبع - توسعة المعاشق | C8: المشاريع | G8: جاري العمل | I8: 45553 | J8: 45560 | K8: =IFERROR(IF(J8="","",IF(G8="مكتملة","✓",J8-TODAY())),"تاريخ غير صحيح") -> -554 | L8: =IF(G8="مكتملة","🟢 مكتملة",IF(G8="لم تبدأ","⚪ لم تبدأ",IF(J8<TODAY(),"🔴 متأخرة",IF(AND(I8<>"",J8<>"",H8<>"",((TODAY()-I8)/(J8-I8)-H8)>0.3),"🟡 تحتاج متابعة","🟢 في المسار")))) -> 🔴 متأخرة | M8: تعديل المواعيد | N8: المشاريع | P8: September
A9: 7 | B9: اقفال حسابات البنك للشركات المغلقة | C9: المالية | G9: مكتملة | H9: 1 | I9: 45544 | J9: 45551 | K9: =IFERROR(IF(J9="","",IF(G9="مكتملة","✓",J9-TODAY())),"تاريخ غير صحيح") -> ✓ | L9: =IF(G9="مكتملة","🟢 مكتملة",IF(G9="لم تبدأ","⚪ لم تبدأ",IF(J9<TODAY(),"🔴 متأخرة",IF(AND(I9<>"",J9<>"",H9<>"",((TODAY()-I9)/(J9-I9)-H9)>0.3),"🟡 تحتاج متابعة","🟢 في المسار")))) -> 🟢 مكتملة | M9: تم الانتهاء من اقفال 15 حساب | P9: September
A10: 8 | B10: الانتهاء من سياسات الإدارة القانونية | C10: الادارة القانونية | G10: جاري العمل | H10: 0.95 | I10: 45518 | J10: 45565 | K10: =IFERROR(IF(J10="","",IF(G10="مكتملة","✓",J10-TODAY())),"تاريخ غير صحيح") -> -549 | L10: =IF(G10="مكتملة","🟢 مكتملة",IF(G10="لم تبدأ","⚪ لم تبدأ",IF(J10<TODAY(),"🔴 متأخرة",IF(AND(I10<>"",J10<>"",H10<>"",((TODAY()-I10)/(J10-I10)-H10)>0.3),"🟡 تحتاج متابعة","🟢 في المسار")))) -> 🔴 متأخرة | M10: تم ارسال المسودة للرئيس التنفيذي | N10: الرئيس التنفيذي | P10: September
A11: 9 | B11: الانتهاء من سياسات المقاولات | C11: المقاولات | G11: جاري العمل | H11: 0.5 | I11: 45518 | J11: 45565 | K11: =IFERROR(IF(J11="","",IF(G11="مكتملة","✓",J11-TODAY())),"تاريخ غير صحيح") -> -549 | L11: =IF(G11="مكتملة","🟢 مكتملة",IF(G11="لم تبدأ","⚪ لم تبدأ",IF(J11<TODAY(),"🔴 متأخرة",IF(AND(I11<>"",J11<>"",H11<>"",((TODAY()-I11)/(J11-I11)-H11)>0.3),"🟡 تحتاج متابعة","🟢 في المسار")))) -> 🔴 متأخرة | M11: تم استلام مسودة وجاري العمل على تحسينها | N11: المدير التنفيذي للمقاولات - للتحديث | P11: September
A12: 10 | B12: التأمين على الممتلكات | C12: الاستثمار | G12: جاري العمل | H12: 0.75 | I12: 45519 | J12: 45534 | K12: =IFERROR(IF(J12="","",IF(G12="مكتملة","✓",J12-TODAY())),"تاريخ غير صحيح") -> -580 | L12: =IF(G12="مكتملة","🟢 مكتملة",IF(G12="لم تبدأ","⚪ لم تبدأ",IF(J12<TODAY(),"🔴 متأخرة",IF(AND(I12<>"",J12<>"",H12<>"",((TODAY()-I12)/(J12-I12)-H12)>0.3),"🟡 تحتاج متابعة","🟢 في المسار")))) -> 🔴 متأخرة | M12: تم ارسال شهادات انهاء التركيبات (المرقب - القرية - الاحساء) | N12: محمد الحجي - للمتابعة | P12: September
A13: 11 | B13: التمويلات القائمة والمتاحة | C13: الخزينة | G13: مكتملة | H13: 1 | I13: 45536 | J13: 45547 | K13: =IFERROR(IF(J13="","",IF(G13="مكتملة","✓",J13-TODAY())),"تاريخ غير صحيح") -> ✓ | L13: =IF(G13="مكتملة","🟢 مكتملة",IF(G13="لم تبدأ","⚪ لم تبدأ",IF(J13<TODAY(),"🔴 متأخرة",IF(AND(I13<>"",J13<>"",H13<>"",((TODAY()-I13)/(J13-I13)-H13)>0.3),"🟡 تحتاج متابعة","🟢 في المسار")))) -> 🟢 مكتملة | M13: تم استلام | N13: الخزينة | P13: September
A14: 12 | B14: الخطة التشغيلية للقرية الشعبية | C14: الرئيس التنفيذي | G14: جاري العمل | H14: 0.95 | I14: 45480 | K14: =IFERROR(IF(J14="","",IF(G14="مكتملة","✓",J14-TODAY())),"تاريخ غير صحيح") | L14: =IF(G14="مكتملة","🟢 مكتملة",IF(G14="لم تبدأ","⚪ لم تبدأ",IF(J14<TODAY(),"🔴 متأخرة",IF(AND(I14<>"",J14<>"",H14<>"",((TODAY()-I14)/(J14-I14)-H14)>0.3),"🟡 تحتاج متابعة","🟢 في المسار")))) -> 🔴 متأخرة | M14: تم ارسال المسودة للرئيس التنفيذي | N14: الرئيس التنفيذي | P14: September
A15: 13 | B15: الصندوق العقاري | C15: الاستثمار | G15: جاري العمل | H15: 0.5 | I15: 45292 | J15: 45657 | K15: =IFERROR(IF(J15="","",IF(G15="مكتملة","✓",J15-TODAY())),"تاريخ غير صحيح") -> -457 | L15: =IF(G15="مكتملة","🟢 مكتملة",IF(G15="لم تبدأ","⚪ لم تبدأ",IF(J15<TODAY(),"🔴 متأخرة",IF(AND(I15<>"",J15<>"",H15<>"",((TODAY()-I15)/(J15-I15)-H15)>0.3),"🟡 تحتاج متابعة","🟢 في المسار")))) -> 🔴 متأخرة | M15: باقي تعديل اتفاقية التطوير - اتفاقية الايجار المنتهي بالتمليك | N15: الراجحي المالية | P15: September
A16: 14 | B16: المصادقة على رصيد الورثة والتجارة | C16: المدير العام | G16: جاري العمل | H16: 0.5 | I16: 45518 | J16: 45525 | K16: =IFERROR(IF(J16="","",IF(G16="مكتملة","✓",J16-TODAY())),"تاريخ غير صحيح") -> -589 | L16: =IF(G16="مكتملة","🟢 مكتملة",IF(G16="لم تبدأ","⚪ لم تبدأ",IF(J16<TODAY(),"🔴 متأخرة",IF(AND(I16<>"",J16<>"",H16<>"",((TODAY()-I16)/(J16-I16)-H16)>0.3),"🟡 تحتاج متابعة","🟢 في المسار")))) -> 🔴 متأخرة | M16: لايوجد تجاوب | N16: تم التذكير | P16: September
A17: 15 | B17: تحديد خطة حوافز للمرشد للتجارة | C17: المدير العام | G17: جاري العمل | H17: 0.25 | I17: 45536 | J17: 45540 | K17: =IFERROR(IF(J17="","",IF(G17="مكتملة","✓",J17-TODAY())),"تاريخ غير صحيح") -> -574 | L17: =IF(G17="مكتملة","🟢 مكتملة",IF(G17="لم تبدأ","⚪ لم تبدأ",IF(J17<TODAY(),"🔴 متأخرة",IF(AND(I17<>"",J17<>"",H17<>"",((TODAY()-I17)/(J17-I17)-H17)>0.3),"🟡 تحتاج متابعة","🟢 في المسار")))) -> 🔴 متأخرة | M17: تم ارسال بعض الأفكار للإدارة المالية لعمل نموذج مالي | N17: المدير العام - تم التذكير | P17: September
A18: 16 | B18: تطبيق خدمات الامن السيبراني | C18: التقنية | G18: مكتملة | H18: 1 | I18: 45420 | J18: 45535 | K18: =IFERROR(IF(J18="","",IF(G18="مكتملة","✓",J18-TODAY())),"تاريخ غير صحيح") -> ✓ | L18: =IF(G18="مكتملة","🟢 مكتملة",IF(G18="لم تبدأ","⚪ لم تبدأ",IF(J18<TODAY(),"🔴 متأخرة",IF(AND(I18<>"",J18<>"",H18<>"",((TODAY()-I18)/(J18-I18)-H18)>0.3),"🟡 تحتاج متابعة","🟢 في المسار")))) -> 🟢 مكتملة | M18: تم الانتهاء من اعمال التنفيذ | P18: September
A19: 17 | B19: تطوير القرية الشعبية بالاحساء | C19: المشاريع | G19: جاري العمل | H19: 0.9 | I19: 45466 | J19: 45503 | K19: =IFERROR(IF(J19="","",IF(G19="مكتملة","✓",J19-TODAY())),"تاريخ غير صحيح") -> -611 | L19: =IF(G19="مكتملة","🟢 مكتملة",IF(G19="لم تبدأ","⚪ لم تبدأ",IF(J19<TODAY(),"🔴 متأخرة",IF(AND(I19<>"",J19<>"",H19<>"",((TODAY()-I19)/(J19-I19)-H19)>0.3),"🟡 تحتاج متابعة","🟢 في المسار")))) -> 🔴 متأخرة | M19: تم الانتهاء من اعمال المقاولات متبقى اعمال العزل | N19: تم اسناد اعمال العزل مع اعمالنا | P19: September
A20: 18 | B20: تطوير سوق الطائف | C20: المشاريع | G20: جاري العمل | H20: 0.95 | I20: 45454 | J20: 45519 | K20: =IFERROR(IF(J20="","",IF(G20="مكتملة","✓",J20-TODAY())),"تاريخ غير صحيح") -> -595 | L20: =IF(G20="مكتملة","🟢 مكتملة",IF(G20="لم تبدأ","⚪ لم تبدأ",IF(J20<TODAY(),"🔴 متأخرة",IF(AND(I20<>"",J20<>"",H20<>"",((TODAY()-I20)/(J20-I20)-H20)>0.3),"🟡 تحتاج متابعة","🟢 في المسار")))) -> 🔴 متأخرة | M20: متبقي بعض اعمال السور وتوقف المقاول وتم رفع الامر للقانونية | N20: إدارة المشاريع - استلام الموقع | P20: September
A21: 19 | B21: تعديل الهيكل التنظيمي للمرشد للتجارة | C21: المدير العام | G21: مكتملة | H21: 1 | I21: 45530 | J21: 45532 | K21: =IFERROR(IF(J21="","",IF(G21="مكتملة","✓",J21-TODAY())),"تاريخ غير صحيح") -> ✓ | L21: =IF(G21="مكتملة","🟢 مكتملة",IF(G21="لم تبدأ","⚪ لم تبدأ",IF(J21<TODAY(),"🔴 متأخرة",IF(AND(I21<>"",J21<>"",H21<>"",((TODAY()-I21)/(J21-I21)-H21)>0.3),"🟡 تحتاج متابعة","🟢 في المسار")))) -> 🟢 مكتملة | M21: تم استلام التعديل على الهيكل التنظيمي في انتظار التعميم | N21: الرئيس التنفيذي - اعتماد | O21: يعتمد | P21: September
A22: 20 | B22: تعديل خطاب الإدارة من قبل المراجع | C22: المالية | G22: مكتملة | H22: 0.95 | I22: 45518 | J22: 45525 | K22: =IFERROR(IF(J22="","",IF(G22="مكتملة","✓",J22-TODAY())),"تاريخ غير صحيح") -> ✓ | L22: =IF(G22="مكتملة","🟢 مكتملة",IF(G22="لم تبدأ","⚪ لم تبدأ",IF(J22<TODAY(),"🔴 متأخرة",IF(AND(I22<>"",J22<>"",H22<>"",((TODAY()-I22)/(J22-I22)-H22)>0.3),"🟡 تحتاج متابعة","🟢 في المسار")))) -> 🟢 مكتملة | M22: تم الرد من المراجع الخارجي | N22: تم الرفع للجنة المراجعة | P22: September
A23: 21 | B23: تعديل سياسة التأجير | C23: الأصول العقارية | G23: جاري العمل | H23: 0.95 | I23: 45537 | J23: 45550 | K23: =IFERROR(IF(J23="","",IF(G23="مكتملة","✓",J23-TODAY())),"تاريخ غير صحيح") -> -564 | L23: =IF(G23="مكتملة","🟢 مكتملة",IF(G23="لم تبدأ","⚪ لم تبدأ",IF(J23<TODAY(),"🔴 متأخرة",IF(AND(I23<>"",J23<>"",H23<>"",((TODAY()-I23)/(J23-I23)-H23)>0.3),"🟡 تحتاج متابعة","🟢 في المسار")))) -> 🔴 متأخرة | M23: تم ارسال النسخة الأخيرة | N23: الرئيس التنفيذي | P23: September
A24: 22 | B24: تقارير دينامكس | C24: التقنية | G24: مكتملة | H24: 1 | I24: 45447 | J24: 45539 | K24: =IFERROR(IF(J24="","",IF(G24="مكتملة","✓",J24-TODAY())),"تاريخ غير صحيح") -> ✓ | L24: =IF(G24="مكتملة","🟢 مكتملة",IF(G24="لم تبدأ","⚪ لم تبدأ",IF(J24<TODAY(),"🔴 متأخرة",IF(AND(I24<>"",J24<>"",H24<>"",((TODAY()-I24)/(J24-I24)-H24)>0.3),"🟡 تحتاج متابعة","🟢 في المسار")))) -> 🟢 مكتملة | M24: تم رفع التحديث والانتهاء من جميع الملاحظات | P24: September
A25: 23 | B25: تقديم توصية لما يمكن اتلافه من مخزون 2017 الى 2021 | C25: المالية | G25: جاري العمل | H25: 0.9 | I25: 45533 | J25: 45540 | K25: =IFERROR(IF(J25="","",IF(G25="مكتملة","✓",J25-TODAY())),"تاريخ غير صحيح") -> -574 | L25: =IF(G25="مكتملة","🟢 مكتملة",IF(G25="لم تبدأ","⚪ لم تبدأ",IF(J25<TODAY(),"🔴 متأخرة",IF(AND(I25<>"",J25<>"",H25<>"",((TODAY()-I25)/(J25-I25)-H25)>0.3),"🟡 تحتاج متابعة","🟢 في المسار")))) -> 🔴 متأخرة | M25: لم يتم الارسال | N25: المدير العام - للرد والاجتماع مع الإدارة المالية | P25: September
A26: 24 | B26: تقديم خطة بخصوص أوامر الشراء المفتوحة حاليا | C26: المدير العام | G26: مكتملة | H26: 1 | I26: 45533 | J26: 45537 | K26: =IFERROR(IF(J26="","",IF(G26="مكتملة","✓",J26-TODAY())),"تاريخ غير صحيح") -> ✓ | L26: =IF(G26="مكتملة","🟢 مكتملة",IF(G26="لم تبدأ","⚪ لم تبدأ",IF(J26<TODAY(),"🔴 متأخرة",IF(AND(I26<>"",J26<>"",H26<>"",((TODAY()-I26)/(J26-I26)-H26)>0.3),"🟡 تحتاج متابعة","🟢 في المسار")))) -> 🟢 مكتملة | M26: تم تقديم التوصية 9/8 للإدارة المالية للمراجعة وتقديم الرأي | P26: September
A27: 25 | B27: تقديم خطة للتصرف في المخزون لعام 2022 والمقدر بحوالي (5 مليون ريال) | C27: المدير العام | G27: مكتملة | H27: 1 | I27: 45533 | J27: 45546 | K27: =IFERROR(IF(J27="","",IF(G27="مكتملة","✓",J27-TODAY())),"تاريخ غير صحيح") -> ✓ | L27: =IF(G27="مكتملة","🟢 مكتملة",IF(G27="لم تبدأ","⚪ لم تبدأ",IF(J27<TODAY(),"🔴 متأخرة",IF(AND(I27<>"",J27<>"",H27<>"",((TODAY()-I27)/(J27-I27)-H27)>0.3),"🟡 تحتاج متابعة","🟢 في المسار")))) -> 🟢 مكتملة | M27: تم التوصية بخصم اجمال 823 الف | N27: المدير العام له صلاحية توزيع الخصومات | P27: September
A28: 26 | B28: تقييم ارض الاحساء لغرض اثباتها في الدفاتر | C28: تطوير الاعمال | G28: جاري العمل | H28: 0.8 | I28: 45536 | J28: 45547 | K28: =IFERROR(IF(J28="","",IF(G28="مكتملة","✓",J28-TODAY())),"تاريخ غير صحيح") -> -567 | L28: =IF(G28="مكتملة","🟢 مكتملة",IF(G28="لم تبدأ","⚪ لم تبدأ",IF(J28<TODAY(),"🔴 متأخرة",IF(AND(I28<>"",J28<>"",H28<>"",((TODAY()-I28)/(J28-I28)-H28)>0.3),"🟡 تحتاج متابعة","🟢 في المسار")))) -> 🔴 متأخرة | M28: تم تعميد مكتب تقييم ومتوقع الانتهاء خلال اسبوع | N28: إدارة تطوير الاعمال | P28: September
A29: 27 | B29: تكوين لجنة والبدء لجرد المخزون | C29: المالية | G29: مكتملة | H29: 1 | I29: 45533 | J29: 45536 | K29: =IFERROR(IF(J29="","",IF(G29="مكتملة","✓",J29-TODAY())),"تاريخ غير صحيح") -> ✓ | L29: =IF(G29="مكتملة","🟢 مكتملة",IF(G29="لم تبدأ","⚪ لم تبدأ",IF(J29<TODAY(),"🔴 متأخرة",IF(AND(I29<>"",J29<>"",H29<>"",((TODAY()-I29)/(J29-I29)-H29)>0.3),"🟡 تحتاج متابعة","🟢 في المسار")))) -> 🟢 مكتملة | M29: تم تشكيل اللجان المختصة بكل فرع | N29: محمد عبد الحميد | P29: September
A30: 28 | B30: حملة اعلامة لتدشين افتتاح أسواق القرية بالحفر | C30: تطوير الاعمال | G30: مكتملة | H30: 0.5 | I30: 45529 | J30: 45657 | K30: =IFERROR(IF(J30="","",IF(G30="مكتملة","✓",J30-TODAY())),"تاريخ غير صحيح") -> ✓ | L30: =IF(G30="مكتملة","🟢 مكتملة",IF(G30="لم تبدأ","⚪ لم تبدأ",IF(J30<TODAY(),"🔴 متأخرة",IF(AND(I30<>"",J30<>"",H30<>"",((TODAY()-I30)/(J30-I30)-H30)>0.3),"🟡 تحتاج متابعة","🟢 في المسار")))) -> 🟢 مكتملة | M30: تم التواصل مع إدارة تطوير الاعمال على ان يتم البدء قبل نهاية العام | P30: September
A31: 29 | B31: خطة التدفق النقدي لمشروعات اعمالنا للمقاولات | C31: المقاولات | G31: مكتملة | H31: 1 | I31: 45511 | J31: 45534 | K31: =IFERROR(IF(J31="","",IF(G31="مكتملة","✓",J31-TODAY())),"تاريخ غير صحيح") -> ✓ | L31: =IF(G31="مكتملة","🟢 مكتملة",IF(G31="لم تبدأ","⚪ لم تبدأ",IF(J31<TODAY(),"🔴 متأخرة",IF(AND(I31<>"",J31<>"",H31<>"",((TODAY()-I31)/(J31-I31)-H31)>0.3),"🟡 تحتاج متابعة","🟢 في المسار")))) -> 🟢 مكتملة | M31: تم الاستلام بتاريخ 9/9 | N31: المدير التنفيذي للمقاولات - باقي المشاريع | P31: September
A32: 30 | B32: خطة المقاول لتحقيق النسبة المخطط لها 73% بنهاية 2024 | C32: المشاريع | G32: مكتملة | H32: 1 | I32: 45536 | J32: 45540 | K32: =IFERROR(IF(J32="","",IF(G32="مكتملة","✓",J32-TODAY())),"تاريخ غير صحيح") -> ✓ | L32: =IF(G32="مكتملة","🟢 مكتملة",IF(G32="لم تبدأ","⚪ لم تبدأ",IF(J32<TODAY(),"🔴 متأخرة",IF(AND(I32<>"",J32<>"",H32<>"",((TODAY()-I32)/(J32-I32)-H32)>0.3),"🟡 تحتاج متابعة","🟢 في المسار")))) -> 🟢 مكتملة | M32: تم استلام خطة المقاول واعتمادها من الاستشاري | N32: تم الاستلام | P32: September
A33: 31 | B33: خطة عدد المستأجرين وعقودهم | C33: الأصول العقارية | G33: مكتملة | H33: 1 | I33: 45537 | J33: 45550 | K33: =IFERROR(IF(J33="","",IF(G33="مكتملة","✓",J33-TODAY())),"تاريخ غير صحيح") -> ✓ | L33: =IF(G33="مكتملة","🟢 مكتملة",IF(G33="لم تبدأ","⚪ لم تبدأ",IF(J33<TODAY(),"🔴 متأخرة",IF(AND(I33<>"",J33<>"",H33<>"",((TODAY()-I33)/(J33-I33)-H33)>0.3),"🟡 تحتاج متابعة","🟢 في المسار")))) -> 🟢 مكتملة | M33: تم الارسال من الأصول العقارية | N33: تم ارسال المتطلبات بتاريخه 8/9 | P33: September
A34: 32 | B34: دراسة الإستحواذ على حصة الشركاء بالشركة العربية | C34: الاستثمار | G34: جاري العمل | H34: 0.95 | I34: 45536 | J34: 45555 | K34: =IFERROR(IF(J34="","",IF(G34="مكتملة","✓",J34-TODAY())),"تاريخ غير صحيح") -> -559 | L34: =IF(G34="مكتملة","🟢 مكتملة",IF(G34="لم تبدأ","⚪ لم تبدأ",IF(J34<TODAY(),"🔴 متأخرة",IF(AND(I34<>"",J34<>"",H34<>"",((TODAY()-I34)/(J34-I34)-H34)>0.3),"🟡 تحتاج متابعة","🟢 في المسار")))) -> 🔴 متأخرة | M34: تم الانتهاء من الدراسة | N34: الرئيس التنفيذي | P34: September
A35: 33 | B35: دراسة بيع 30% من مشروع اشبيلية | C35: الاستثمار | G35: جاري العمل | H35: 0.95 | I35: 45536 | J35: 45580 | K35: =IFERROR(IF(J35="","",IF(G35="مكتملة","✓",J35-TODAY())),"تاريخ غير صحيح") -> -534 | L35: =IF(G35="مكتملة","🟢 مكتملة",IF(G35="لم تبدأ","⚪ لم تبدأ",IF(J35<TODAY(),"🔴 متأخرة",IF(AND(I35<>"",J35<>"",H35<>"",((TODAY()-I35)/(J35-I35)-H35)>0.3),"🟡 تحتاج متابعة","🟢 في المسار")))) -> 🔴 متأخرة | M35: تم الانتهاء من الدراسة | N35: الرئيس التنفيذي | P35: September
A36: 34 | B36: دراسة جدوى القطاع التجاري | C36: المدير العام | G36: جاري العمل | H36: 0.85 | I36: 45496 | J36: 45554 | K36: =IFERROR(IF(J36="","",IF(G36="مكتملة","✓",J36-TODAY())),"تاريخ غير صحيح") -> -560 | L36: =IF(G36="مكتملة","🟢 مكتملة",IF(G36="لم تبدأ","⚪ لم تبدأ",IF(J36<TODAY(),"🔴 متأخرة",IF(AND(I36<>"",J36<>"",H36<>"",((TODAY()-I36)/(J36-I36)-H36)>0.3),"🟡 تحتاج متابعة","🟢 في المسار")))) -> 🔴 متأخرة | M36: تم استلام الإصدار الأول من التقرير | N36: المرشد للتجارة - الإدارة المالية - الاستثمار للمراجعة | P36: September
A37: 35 | B37: دراسة حركة المرور بسوق خضار المدينة | C37: المشاريع | G37: جاري العمل | H37: 0.95 | I37: 45431 | J37: 45519 | K37: =IFERROR(IF(J37="","",IF(G37="مكتملة","✓",J37-TODAY())),"تاريخ غير صحيح") -> -595 | L37: =IF(G37="مكتملة","🟢 مكتملة",IF(G37="لم تبدأ","⚪ لم تبدأ",IF(J37<TODAY(),"🔴 متأخرة",IF(AND(I37<>"",J37<>"",H37<>"",((TODAY()-I37)/(J37-I37)-H37)>0.3),"🟡 تحتاج متابعة","🟢 في المسار")))) -> 🔴 متأخرة | M37: تم ارسال العروض للرئيس التنفيذي | N37: الرئيس التنفيذي - On Hold | P37: September
A38: 36 | B38: ربط الدينامكس مع منصة الزكاة | C38: التقنية | G38: مكتملة | H38: 1 | I38: 45522 | J38: 45555 | K38: =IFERROR(IF(J38="","",IF(G38="مكتملة","✓",J38-TODAY())),"تاريخ غير صحيح") -> ✓ | L38: =IF(G38="مكتملة","🟢 مكتملة",IF(G38="لم تبدأ","⚪ لم تبدأ",IF(J38<TODAY(),"🔴 متأخرة",IF(AND(I38<>"",J38<>"",H38<>"",((TODAY()-I38)/(J38-I38)-H38)>0.3),"🟡 تحتاج متابعة","🟢 في المسار")))) -> 🟢 مكتملة | M38: بانظار تحديد الموعد والبدء بعمل التجارب خلال شهر | N38: تم الانتهاء من الفواتير الالكترونية | P38: September
A39: 37 | B39: صلاحيات المبيعات والمشتريات بالدينامكس | C39: التقنية | G39: مكتملة | H39: 1 | I39: 45543 | J39: 45550 | K39: =IFERROR(IF(J39="","",IF(G39="مكتملة","✓",J39-TODAY())),"تاريخ غير صحيح") -> ✓ | L39: =IF(G39="مكتملة","🟢 مكتملة",IF(G39="لم تبدأ","⚪ لم تبدأ",IF(J39<TODAY(),"🔴 متأخرة",IF(AND(I39<>"",J39<>"",H39<>"",((TODAY()-I39)/(J39-I39)-H39)>0.3),"🟡 تحتاج متابعة","🟢 في المسار")))) -> 🟢 مكتملة | M39: تم إتمام الصلاحيات وتنفيذ المطلوب | N39: التقنية - إتمام الصلاحيات على النظام | P39: September
A40: 38 | B40: صيانة سوق المرقب | C40: المشاريع | G40: جاري العمل | H40: 0.9 | I40: 45448 | J40: 45559 | K40: =IFERROR(IF(J40="","",IF(G40="مكتملة","✓",J40-TODAY())),"تاريخ غير صحيح") -> -555 | L40: =IF(G40="مكتملة","🟢 مكتملة",IF(G40="لم تبدأ","⚪ لم تبدأ",IF(J40<TODAY(),"🔴 متأخرة",IF(AND(I40<>"",J40<>"",H40<>"",((TODAY()-I40)/(J40-I40)-H40)>0.3),"🟡 تحتاج متابعة","🟢 في المسار")))) -> 🔴 متأخرة | M40: متبقى دورات المياة - ويتم التجديد على مراحل كل مرحلة دورة مياة واحدة | N40: إدارة المشاريع - استلام الموقع | P40: September
...

Sheet المهام النشطة 2026
G1: المهام النشطة لعام 2026 – لوحة المتابعة التنفيذية
A2: # | B2: المهمة | C2: القسم | D2: المسؤول | E2: الأولوية | F2: الركيزة الاستراتيجية | G2: الحالة | H2: نسبة الإنجاز | I2: تاريخ البداية | J2: تاريخ الانتهاء | K2: الأيام المتبقية | L2: مؤشر المخاطر | M2: الملاحظات | N2: الخطوة القادمة | O2: ملاحظات الرئيس التنفيذي | P2: الشهر المصدر
A3: 1 | B3: إتمام داشبورد الموازنة | C3: المالية | D3: عادل جلال | E3: P2 - مهم | F3: التحول الرقمي | G3: جاري العمل | H3: 0.5 | I3: 45736 | J3: 45777 | K3: =IFERROR(IF(J3="","",IF(G3="مكتملة","✓",J3-TODAY())),"تاريخ غير صحيح") -> -337 | L3: =IF(G3="مكتملة","🟢 مكتملة",IF(G3="لم تبدأ","⚪ لم تبدأ",IF(J3<TODAY(),"🔴 متأخرة",IF(AND(I3<>"",J3<>"",H3<>"",((TODAY()-I3)/(J3-I3)-H3)>0.3),"🟡 تحتاج متابعة","🟢 في المسار")))) -> 🔴 متأخرة | M3: جاري العمل مع المورد لتحديد نطاق العمل والتسعير | P3: 2026 Tasks
A4: 2 | B4: ادخال داتا الإدارة القانونية على الدينامكس | C4: الادارة القانونية | D4: منصور القعود | G4: مكتملة | H4: 1 | I4: 45735 | J4: 45777 | K4: =IFERROR(IF(J4="","",IF(G4="مكتملة","✓",J4-TODAY())),"تاريخ غير صحيح") -> ✓ | L4: =IF(G4="مكتملة","🟢 مكتملة",IF(G4="لم تبدأ","⚪ لم تبدأ",IF(J4<TODAY(),"🔴 متأخرة",IF(AND(I4<>"",J4<>"",H4<>"",((TODAY()-I4)/(J4-I4)-H4)>0.3),"🟡 تحتاج متابعة","🟢 في المسار")))) -> 🟢 مكتملة | M4: تم ادخال داتا القانونية كاملة لكن تم رفض 23 مطالبة من المالية لعدم تطابق الرصيد | N4: مكتمل | P4: 2026 Tasks
A5: 3 | B5: اطلاق برنامج مصادقة ارصدة عملاء الأصول العقارية | C5: التقنية | D5: مرتضى إبراهيم | G5: مكتملة | H5: 1 | J5: 45778 | K5: =IFERROR(IF(J5="","",IF(G5="مكتملة","✓",J5-TODAY())),"تاريخ غير صحيح") -> ✓ | L5: =IF(G5="مكتملة","🟢 مكتملة",IF(G5="لم تبدأ","⚪ لم تبدأ",IF(J5<TODAY(),"🔴 متأخرة",IF(AND(I5<>"",J5<>"",H5<>"",((TODAY()-I5)/(J5-I5)-H5)>0.3),"🟡 تحتاج متابعة","🟢 في المسار")))) -> 🟢 مكتملة | M5: تم تجربة التطبيق بواسطة التقنية واعتماده من ناحيتهم باقي اعتماد الإدارة المالية عن | N5: مكتمل | P5: 2026 Tasks
A6: 4 | B6: اغلاق السجل التجاري للتقنيه | C6: الادارة القانونية | D6: منصور القعود | G6: مكتملة | H6: 1 | K6: =IFERROR(IF(J6="","",IF(G6="مكتملة","✓",J6-TODAY())),"تاريخ غير صحيح") | L6: =IF(G6="مكتملة","🟢 مكتملة",IF(G6="لم تبدأ","⚪ لم تبدأ",IF(J6<TODAY(),"🔴 متأخرة",IF(AND(I6<>"",J6<>"",H6<>"",((TODAY()-I6)/(J6-I6)-H6)>0.3),"🟡 تحتاج متابعة","🟢 في المسار")))) -> 🟢 مكتملة | M6: تم سداد رسوم طلب شطب السجل | N6: مكتمل | P6: 2026 Tasks
A7: 5 | B7: اختبار الدينامكس والتأكيد على انه جاهز للاقفال الشهري | C7: التقنية | D7: مرتضى إبراهيم | G7: مكتملة | H7: 1 | I7: 45757 | J7: 45761 | K7: =IFERROR(IF(J7="","",IF(G7="مكتملة","✓",J7-TODAY())),"تاريخ غير صحيح") -> ✓ | L7: =IF(G7="مكتملة","🟢 مكتملة",IF(G7="لم تبدأ","⚪ لم تبدأ",IF(J7<TODAY(),"🔴 متأخرة",IF(AND(I7<>"",J7<>"",H7<>"",((TODAY()-I7)/(J7-I7)-H7)>0.3),"🟡 تحتاج متابعة","🟢 في المسار")))) -> 🟢 مكتملة | M7: بعد التعديلات الأخيرة (قيد التسوية - حل مشكلة الضريبة) | N7: جاهز لاقفال شهر مايو | P7: 2026 Tasks
A8: 6 | B8: داشبورد الأصول العقارية وربطها بداشبورد القانونية | C8: التقنية | D8: مرتضى إبراهيم | G8: مكتملة | H8: 1 | J8: 45791 | K8: =IFERROR(IF(J8="","",IF(G8="مكتملة","✓",J8-TODAY())),"تاريخ غير صحيح") -> ✓ | L8: =IF(G8="مكتملة","🟢 مكتملة",IF(G8="لم تبدأ","⚪ لم تبدأ",IF(J8<TODAY(),"🔴 متأخرة",IF(AND(I8<>"",J8<>"",H8<>"",((TODAY()-I8)/(J8-I8)-H8)>0.3),"🟡 تحتاج متابعة","🟢 في المسار")))) -> 🟢 مكتملة | M8: يتم إضافة ماتم تحويله للقانونية في اعمار الديون | N8: تم الانتهاء من ربطهم الاثنين مع بعض | P8: 2026 Tasks
A9: 7 | B9: تقديم عرض التقنية العقارية Prop Tech | C9: الاستثمار | D9: معتصم العقاد | G9: مكتملة | H9: 1 | K9: =IFERROR(IF(J9="","",IF(G9="مكتملة","✓",J9-TODAY())),"تاريخ غير صحيح") | L9: =IF(G9="مكتملة","🟢 مكتملة",IF(G9="لم تبدأ","⚪ لم تبدأ",IF(J9<TODAY(),"🔴 متأخرة",IF(AND(I9<>"",J9<>"",H9<>"",((TODAY()-I9)/(J9-I9)-H9)>0.3),"🟡 تحتاج متابعة","🟢 في المسار")))) -> 🟢 مكتملة | M9: تم الارسال للرئيس | N9: للمناقشة مع الرئيس | P9: 2026 Tasks
A10: 8 | B10: ضاحية الفرسان | C10: الاستثمار | D10: معتصم العقاد | E10: P3 - عادي | F10: نمو الإيرادات | G10: منتهي | H10: 0.5 | J10: 46387 | K10: =IFERROR(IF(J10="","",IF(G10="مكتملة","✓",J10-TODAY())),"تاريخ غير صحيح") -> 273 | L10: =IF(G10="مكتملة","🟢 مكتملة",IF(G10="لم تبدأ","⚪ لم تبدأ",IF(J10<TODAY(),"🔴 متأخرة",IF(AND(I10<>"",J10<>"",H10<>"",((TODAY()-I10)/(J10-I10)-H10)>0.3),"🟡 تحتاج متابعة","🟢 في المسار")))) -> 🟢 في المسار | M10: ارسلوا مجموعة الاستفسارات والمخاوف بخصوص سكن العمالة وآليات تشغيل السوق | N10: في انتظار الرد منهم | P10: 2026 Tasks
A11: 9 | B11: انشاء صندوق عقاري مع احد شركات التمويل | C11: الرئيس التنفيذي | D11: الرئيس التنفيذي | E11: P3 - عادي | F11: نمو الإيرادات | G11: جاري العمل | H11: 0 | J11: 46387 | K11: =IFERROR(IF(J11="","",IF(G11="مكتملة","✓",J11-TODAY())),"تاريخ غير صحيح") -> 273 | L11: =IF(G11="مكتملة","🟢 مكتملة",IF(G11="لم تبدأ","⚪ لم تبدأ",IF(J11<TODAY(),"🔴 متأخرة",IF(AND(I11<>"",J11<>"",H11<>"",((TODAY()-I11)/(J11-I11)-H11)>0.3),"🟡 تحتاج متابعة","🟢 في المسار")))) -> 🟢 في المسار | N11: لم يتم الرد | P11: 2026 Tasks
A12: 10 | B12: فيديو اشبيليه و حفر الجديد للعرض على المجلس | C12: المشاريع | D12: اشرف سمير | G12: مكتملة | H12: 1 | K12: =IFERROR(IF(J12="","",IF(G12="مكتملة","✓",J12-TODAY())),"تاريخ غير صحيح") | L12: =IF(G12="مكتملة","🟢 مكتملة",IF(G12="لم تبدأ","⚪ لم تبدأ",IF(J12<TODAY(),"🔴 متأخرة",IF(AND(I12<>"",J12<>"",H12<>"",((TODAY()-I12)/(J12-I12)-H12)>0.3),"🟡 تحتاج متابعة","🟢 في المسار")))) -> 🟢 مكتملة | M12: تم الاستلام | P12: 2026 Tasks
A13: 11 | B13: تطبيق مصادقة ارصدة العملاء | C13: التقنية | D13: مرتضى إبراهيم | E13: P2 - مهم | F13: التحول الرقمي | G13: جاري العمل | H13: 1 | J13: 46022 | K13: =IFERROR(IF(J13="","",IF(G13="مكتملة","✓",J13-TODAY())),"تاريخ غير صحيح") -> -92 | L13: =IF(G13="مكتملة","🟢 مكتملة",IF(G13="لم تبدأ","⚪ لم تبدأ",IF(J13<TODAY(),"🔴 متأخرة",IF(AND(I13<>"",J13<>"",H13<>"",((TODAY()-I13)/(J13-I13)-H13)>0.3),"🟡 تحتاج متابعة","🟢 في المسار")))) -> 🔴 متأخرة | M13: تم ارسال ايميل للبدء في الاستخدام بحد اقصى الخميس 2/4/26 | N13: تم التحديث 29/3 | P13: 2026 Tasks
A14: 12 | B14: تقديم دراسة من BDO بشكل احترافي | C14: المالية | D14: محمد عبدالحميد | G14: مكتملة | H14: 1 | K14: =IFERROR(IF(J14="","",IF(G14="مكتملة","✓",J14-TODAY())),"تاريخ غير صحيح") | L14: =IF(G14="مكتملة","🟢 مكتملة",IF(G14="لم تبدأ","⚪ لم تبدأ",IF(J14<TODAY(),"🔴 متأخرة",IF(AND(I14<>"",J14<>"",H14<>"",((TODAY()-I14)/(J14-I14)-H14)>0.3),"🟡 تحتاج متابعة","🟢 في المسار")))) -> 🟢 مكتملة | M14: تم استلام التقرير | N14: مع وجود بعض الملحوظات وفي انتظار Cfo للنقاش | P14: 2026 Tasks
A15: 13 | B15: اعداد دراسة المخاطر حسب طلب لجنة المراجعة | C15: الاستراتيجية | D15: محمد زاهر | G15: مكتملة | H15: 1 | K15: =IFERROR(IF(J15="","",IF(G15="مكتملة","✓",J15-TODAY())),"تاريخ غير صحيح") | L15: =IF(G15="مكتملة","🟢 مكتملة",IF(G15="لم تبدأ","⚪ لم تبدأ",IF(J15<TODAY(),"🔴 متأخرة",IF(AND(I15<>"",J15<>"",H15<>"",((TODAY()-I15)/(J15-I15)-H15)>0.3),"🟡 تحتاج متابعة","🟢 في المسار")))) -> 🟢 مكتملة | M15: تم استلام ردود من جميع الإدارات | P15: 2026 Tasks
A16: 14 | B16: معالجة اثر انخفاض إيرادات سوق المرقب | C16: الأصول العقارية | D16: محمد الخضيرة | G16: مكتملة | H16: 1 | J16: 45838 | K16: =IFERROR(IF(J16="","",IF(G16="مكتملة","✓",J16-TODAY())),"تاريخ غير صحيح") -> ✓ | L16: =IF(G16="مكتملة","🟢 مكتملة",IF(G16="لم تبدأ","⚪ لم تبدأ",IF(J16<TODAY(),"🔴 متأخرة",IF(AND(I16<>"",J16<>"",H16<>"",((TODAY()-I16)/(J16-I16)-H16)>0.3),"🟡 تحتاج متابعة","🟢 في المسار")))) -> 🟢 مكتملة | M16: تم العرض والموافقة من الرئيس | P16: 2026 Tasks
A17: 15 | B17: التحقق من مشكلة تحويل قيمة العقد إلى ممثل الشركة في العقار | C17: الادارة القانونية | D17: منصور القعود | G17: مكتملة | H17: 1 | K17: =IFERROR(IF(J17="","",IF(G17="مكتملة","✓",J17-TODAY())),"تاريخ غير صحيح") | L17: =IF(G17="مكتملة","🟢 مكتملة",IF(G17="لم تبدأ","⚪ لم تبدأ",IF(J17<TODAY(),"🔴 متأخرة",IF(AND(I17<>"",J17<>"",H17<>"",((TODAY()-I17)/(J17-I17)-H17)>0.3),"🟡 تحتاج متابعة","🟢 في المسار")))) -> 🟢 مكتملة | M17: تم الانتهاء | P17: 2026 Tasks
A18: 16 | B18: إضافة القانونية في سلسلة موافقات إخلاء الطرف. | C18: الادارة القانونية | D18: منصور القعود | G18: مكتملة | H18: 1 | K18: =IFERROR(IF(J18="","",IF(G18="مكتملة","✓",J18-TODAY())),"تاريخ غير صحيح") | L18: =IF(G18="مكتملة","🟢 مكتملة",IF(G18="لم تبدأ","⚪ لم تبدأ",IF(J18<TODAY(),"🔴 متأخرة",IF(AND(I18<>"",J18<>"",H18<>"",((TODAY()-I18)/(J18-I18)-H18)>0.3),"🟡 تحتاج متابعة","🟢 في المسار")))) -> 🟢 مكتملة | M18: مكتمله | P18: 2026 Tasks
A19: 17 | B19: التأكيد على أن جميع خدمات القانونية تتم عن طريق الدينامكس بما فيها طلبات المساهمين. | C19: الادارة القانونية | D19: منصور القعود | G19: مكتملة | H19: 1 | K19: =IFERROR(IF(J19="","",IF(G19="مكتملة","✓",J19-TODAY())),"تاريخ غير صحيح") | L19: =IF(G19="مكتملة","🟢 مكتملة",IF(G19="لم تبدأ","⚪ لم تبدأ",IF(J19<TODAY(),"🔴 متأخرة",IF(AND(I19<>"",J19<>"",H19<>"",((TODAY()-I19)/(J19-I19)-H19)>0.3),"🟡 تحتاج متابعة","🟢 في المسار")))) -> 🟢 مكتملة | M19: مكتملة | P19: 2026 Tasks
A20: 18 | B20: إضافة القضايا المرفوعة في القانونية إلى داشبورد أعمار الديون. | C20: التقنية | D20: مرتضى إبراهيم | G20: مكتملة | H20: 1 | K20: =IFERROR(IF(J20="","",IF(G20="مكتملة","✓",J20-TODAY())),"تاريخ غير صحيح") | L20: =IF(G20="مكتملة","🟢 مكتملة",IF(G20="لم تبدأ","⚪ لم تبدأ",IF(J20<TODAY(),"🔴 متأخرة",IF(AND(I20<>"",J20<>"",H20<>"",((TODAY()-I20)/(J20-I20)-H20)>0.3),"🟡 تحتاج متابعة","🟢 في المسار")))) -> 🟢 مكتملة | M20: تم الانتهاء منها | P20: 2026 Tasks
A21: 19 | B21: إضافة تاريخ انتهاء الوكالة وحالتها (منتهية - سارية) | C21: التقنية | D21: مرتضى إبراهيم | G21: مكتملة | H21: 1 | K21: =IFERROR(IF(J21="","",IF(G21="مكتملة","✓",J21-TODAY())),"تاريخ غير صحيح") | L21: =IF(G21="مكتملة","🟢 مكتملة",IF(G21="لم تبدأ","⚪ لم تبدأ",IF(J21<TODAY(),"🔴 متأخرة",IF(AND(I21<>"",J21<>"",H21<>"",((TODAY()-I21)/(J21-I21)-H21)>0.3),"🟡 تحتاج متابعة","🟢 في المسار")))) -> 🟢 مكتملة | P21: 2026 Tasks
A22: 20 | B22: هيكل التكاليف المثالي | C22: المالية | D22: محمد عبدالحميد | G22: مكتملة | H22: 1 | K22: =IFERROR(IF(J22="","",IF(G22="مكتملة","✓",J22-TODAY())),"تاريخ غير صحيح") | L22: =IF(G22="مكتملة","🟢 مكتملة",IF(G22="لم تبدأ","⚪ لم تبدأ",IF(J22<TODAY(),"🔴 متأخرة",IF(AND(I22<>"",J22<>"",H22<>"",((TODAY()-I22)/(J22-I22)-H22)>0.3),"🟡 تحتاج متابعة","🟢 في المسار")))) -> 🟢 مكتملة | M22: تعديل التكاليف وحذف التكاليف الغير مسيطر عليها | N22: مكتمل | P22: 2026 Tasks
A23: 21 | B23: تعيين استشاري لهيكلة راس المال المثالي | C23: المالية | D23: محمد عبدالحميد | G23: مكتملة | H23: 1 | K23: =IFERROR(IF(J23="","",IF(G23="مكتملة","✓",J23-TODAY())),"تاريخ غير صحيح") | L23: =IF(G23="مكتملة","🟢 مكتملة",IF(G23="لم تبدأ","⚪ لم تبدأ",IF(J23<TODAY(),"🔴 متأخرة",IF(AND(I23<>"",J23<>"",H23<>"",((TODAY()-I23)/(J23-I23)-H23)>0.3),"🟡 تحتاج متابعة","🟢 في المسار")))) -> 🟢 مكتملة | M23: تم الحصول على عرضين وبانتظار قرار لجنة المراجعة. | P23: 2026 Tasks
A24: 22 | B24: جلب عروض المراجع الخارجي (إضافية) | C24: المالية | D24: محمد عبدالحميد | G24: مكتملة | H24: 1 | K24: =IFERROR(IF(J24="","",IF(G24="مكتملة","✓",J24-TODAY())),"تاريخ غير صحيح") | L24: =IF(G24="مكتملة","🟢 مكتملة",IF(G24="لم تبدأ","⚪ لم تبدأ",IF(J24<TODAY(),"🔴 متأخرة",IF(AND(I24<>"",J24<>"",H24<>"",((TODAY()-I24)/(J24-I24)-H24)>0.3),"🟡 تحتاج متابعة","🟢 في المسار")))) -> 🟢 مكتملة | M24: تم اعتذار KPMG بشكل شفهى وابنتظار ايميل بالاعتذار منهم. بخصوص ديلويت مازال تحت الاجراء | N24: تم الارسال | P24: 2026 Tasks
A25: 23 | B25: تغيير اسم قرية الاحساء | C25: الأصول العقارية | D25: محمد الخضيرة | G25: مكتملة | H25: 1 | J25: 45823 | K25: =IFERROR(IF(J25="","",IF(G25="مكتملة","✓",J25-TODAY())),"تاريخ غير صحيح") -> ✓ | L25: =IF(G25="مكتملة","🟢 مكتملة",IF(G25="لم تبدأ","⚪ لم تبدأ",IF(J25<TODAY(),"🔴 متأخرة",IF(AND(I25<>"",J25<>"",H25<>"",((TODAY()-I25)/(J25-I25)-H25)>0.3),"🟡 تحتاج متابعة","🟢 في المسار")))) -> 🟢 مكتملة | M25: تم اعتماد الرئيس لعروض تغيير الأسماء للوحات | N25: مكتمل | P25: 2026 Tasks
A26: 24 | B26: تقرير الإيرادات الأخرى | C26: الأصول العقارية | D26: محمد الخضيرة | G26: مكتملة | H26: 1 | J26: 45843 | K26: =IFERROR(IF(J26="","",IF(G26="مكتملة","✓",J26-TODAY())),"تاريخ غير صحيح") -> ✓ | L26: =IF(G26="مكتملة","🟢 مكتملة",IF(G26="لم تبدأ","⚪ لم تبدأ",IF(J26<TODAY(),"🔴 متأخرة",IF(AND(I26<>"",J26<>"",H26<>"",((TODAY()-I26)/(J26-I26)-H26)>0.3),"🟡 تحتاج متابعة","🟢 في المسار")))) -> 🟢 مكتملة | M26: تفاصيل الإيرادات الأخرى مع المقارنة مع العام الماضي | N26: تم الاستلام | P26: 2026 Tasks
A27: 25 | B27: استراتيجية إدارة المرافق | C27: المشاريع | D27: عوض الغوازي | G27: مكتملة | H27: 1 | K27: =IFERROR(IF(J27="","",IF(G27="مكتملة","✓",J27-TODAY())),"تاريخ غير صحيح") | L27: =IF(G27="مكتملة","🟢 مكتملة",IF(G27="لم تبدأ","⚪ لم تبدأ",IF(J27<TODAY(),"🔴 متأخرة",IF(AND(I27<>"",J27<>"",H27<>"",((TODAY()-I27)/(J27-I27)-H27)>0.3),"🟡 تحتاج متابعة","🟢 في المسار")))) -> 🟢 مكتملة | N27: تم التعديل على ان نستمر بتقديم الخدمة للمستاجرين في عقارات المجموعة فقط | P27: 2026 Tasks
A28: 26 | B28: خطة زيادة إيرادات الأصول العقارية 15% (على مستوى السوق) قبل حلول عام 2027 | C28: الأصول العقارية | D28: محمد الخضيرة | G28: مكتملة | H28: 1 | J28: 45838 | K28: =IFERROR(IF(J28="","",IF(G28="مكتملة","✓",J28-TODAY())),"تاريخ غير صحيح") -> ✓ | L28: =IF(G28="مكتملة","🟢 مكتملة",IF(G28="لم تبدأ","⚪ لم تبدأ",IF(J28<TODAY(),"🔴 متأخرة",IF(AND(I28<>"",J28<>"",H28<>"",((TODAY()-I28)/(J28-I28)-H28)>0.3),"🟡 تحتاج متابعة","🟢 في المسار")))) -> 🟢 مكتملة | M28: تم استلام الخطة واعتمادها من الرئيس | N28: تم التعديل واعتماد ارقام 24 (205 مليون) | P28: 2026 Tasks
A29: 27 | B29: اغلاق تقرير EY الخاص بالتقنية | C29: التقنية | D29: مرتضى إبراهيم | G29: مكتملة | H29: 1 | J29: 45868 | K29: =IFERROR(IF(J29="","",IF(G29="مكتملة","✓",J29-TODAY())),"تاريخ غير صحيح") -> ✓ | L29: =IF(G29="مكتملة","🟢 مكتملة",IF(G29="لم تبدأ","⚪ لم تبدأ",IF(J29<TODAY(),"🔴 متأخرة",IF(AND(I29<>"",J29<>"",H29<>"",((TODAY()-I29)/(J29-I29)-H29)>0.3),"🟡 تحتاج متابعة","🟢 في المسار")))) -> 🟢 مكتملة | M29: جاري العمل مع فريق الامن السيبراني لاغلاق النقاط حسب الموعد المحدد | N29: جاري العمل على النقاط التي سيتم مراجعتها في اجتماع اللجنة القادم | P29: 2026 Tasks
A30: 28 | B30: اثر التحول للمعايير IFRS | C30: المالية | D30: محمد عبدالحميد | G30: مكتملة | H30: 1 | K30: =IFERROR(IF(J30="","",IF(G30="مكتملة","✓",J30-TODAY())),"تاريخ غير صحيح") | L30: =IF(G30="مكتملة","🟢 مكتملة",IF(G30="لم تبدأ","⚪ لم تبدأ",IF(J30<TODAY(),"🔴 متأخرة",IF(AND(I30<>"",J30<>"",H30<>"",((TODAY()-I30)/(J30-I30)-H30)>0.3),"🟡 تحتاج متابعة","🟢 في المسار")))) -> 🟢 مكتملة | M30: تم الانتهاء | N30: تم استلام العرض التقديمي | P30: 2026 Tasks
A31: 29 | B31: بإعداد دراسة استشارية بالتعاون مع شركات متخصصة في خدمات المواقف | C31: الاستثمار | D31: معتصم العقاد | G31: مكتملة | H31: 1 | K31: =IFERROR(IF(J31="","",IF(G31="مكتملة","✓",J31-TODAY())),"تاريخ غير صحيح") | L31: =IF(G31="مكتملة","🟢 مكتملة",IF(G31="لم تبدأ","⚪ لم تبدأ",IF(J31<TODAY(),"🔴 متأخرة",IF(AND(I31<>"",J31<>"",H31<>"",((TODAY()-I31)/(J31-I31)-H31)>0.3),"🟡 تحتاج متابعة","🟢 في المسار")))) -> 🟢 مكتملة | M31: تم الاتفاق على جلب دراسة سعرية لتأجير المواقف | N31: تم الاستلام | P31: 2026 Tasks
A32: 30 | B32: مراجعة السياسات فنيا من قسم التقنية | C32: التقنية | D32: مرتضى إبراهيم | G32: مكتملة | H32: 1 | K32: =IFERROR(IF(J32="","",IF(G32="مكتملة","✓",J32-TODAY())),"تاريخ غير صحيح") | L32: =IF(G32="مكتملة","🟢 مكتملة",IF(G32="لم تبدأ","⚪ لم تبدأ",IF(J32<TODAY(),"🔴 متأخرة",IF(AND(I32<>"",J32<>"",H32<>"",((TODAY()-I32)/(J32-I32)-H32)>0.3),"🟡 تحتاج متابعة","🟢 في المسار")))) -> 🟢 مكتملة | M32: تم الارسال للتقنية للمراجعة | N32: مكتمل -تم الرد | P32: 2026 Tasks
A33: 31 | B33: افادة عن رسوم الاراضي لعقد اشبيلية | C33: الادارة القانونية | D33: منصور القعود | G33: مكتملة | H33: 1 | K33: =IFERROR(IF(J33="","",IF(G33="مكتملة","✓",J33-TODAY())),"تاريخ غير صحيح") | L33: =IF(G33="مكتملة","🟢 مكتملة",IF(G33="لم تبدأ","⚪ لم تبدأ",IF(J33<TODAY(),"🔴 متأخرة",IF(AND(I33<>"",J33<>"",H33<>"",((TODAY()-I33)/(J33-I33)-H33)>0.3),"🟡 تحتاج متابعة","🟢 في المسار")))) -> 🟢 مكتملة | M33: تم الرد من الإدارة القانونية | N33: الصك مملوك لجهة حكومية وبالتالي لا ينطبق عليها نظام رسوم الأراضي البيضاء أما بخصوص الرسوم المفروضة على الأرض طبقا لعقد الإيجار فنفيدكم بأن العقد لم ينص على رسوم معينة وإنما تكلم عن الرسوم بشكل عام أي كان نوعها. | P33: 2026 Tasks
A34: 32 | B34: دليل شامل لبرنامج دينامكس | C34: التقنية | D34: مرتضى إبراهيم | G34: مكتملة | H34: 1 | J34: 45918 | K34: =IFERROR(IF(J34="","",IF(G34="مكتملة","✓",J34-TODAY())),"تاريخ غير صحيح") -> ✓ | L34: =IF(G34="مكتملة","🟢 مكتملة",IF(G34="لم تبدأ","⚪ لم تبدأ",IF(J34<TODAY(),"🔴 متأخرة",IF(AND(I34<>"",J34<>"",H34<>"",((TODAY()-I34)/(J34-I34)-H34)>0.3),"🟡 تحتاج متابعة","🟢 في المسار")))) -> 🟢 مكتملة | M34: تم الاستلام | N34: مكتمل | P34: 2026 Tasks
A35: 33 | B35: التواصل مع منشآت | C35: الموارد البشرية | D35: رياض الزيد | G35: مكتملة | H35: 1 | J35: 45826 | K35: =IFERROR(IF(J35="","",IF(G35="مكتملة","✓",J35-TODAY())),"تاريخ غير صحيح") -> ✓ | L35: =IF(G35="مكتملة","🟢 مكتملة",IF(G35="لم تبدأ","⚪ لم تبدأ",IF(J35<TODAY(),"🔴 متأخرة",IF(AND(I35<>"",J35<>"",H35<>"",((TODAY()-I35)/(J35-I35)-H35)>0.3),"🟡 تحتاج متابعة","🟢 في المسار")))) -> 🟢 مكتملة | M35: تقديم تقرير عن البرامج المقدمة من منشآت | P35: 2026 Tasks
A36: 34 | B36: دورة تدريبية اونلاين لادارة المرافق | C36: المشاريع | D36: عوض الغوازي | G36: مكتملة | H36: 1 | J36: 45825 | K36: =IFERROR(IF(J36="","",IF(G36="مكتملة","✓",J36-TODAY())),"تاريخ غير صحيح") -> ✓ | L36: =IF(G36="مكتملة","🟢 مكتملة",IF(G36="لم تبدأ","⚪ لم تبدأ",IF(J36<TODAY(),"🔴 متأخرة",IF(AND(I36<>"",J36<>"",H36<>"",((TODAY()-I36)/(J36-I36)-H36)>0.3),"🟡 تحتاج متابعة","🟢 في المسار")))) -> 🟢 مكتملة | M36: حضور الدورة لمنسوبي إدارة المرافق | N36: تم حضور 5 اشخاص | P36: 2026 Tasks
A37: 35 | B37: اقفال شهر مايو | C37: المالية | D37: محمد عبدالحميد | G37: مكتملة | H37: 1 | J37: 45826 | K37: =IFERROR(IF(J37="","",IF(G37="مكتملة","✓",J37-TODAY())),"تاريخ غير صحيح") -> ✓ | L37: =IF(G37="مكتملة","🟢 مكتملة",IF(G37="لم تبدأ","⚪ لم تبدأ",IF(J37<TODAY(),"🔴 متأخرة",IF(AND(I37<>"",J37<>"",H37<>"",((TODAY()-I37)/(J37-I37)-H37)>0.3),"🟡 تحتاج متابعة","🟢 في المسار")))) -> 🟢 مكتملة | N37: مستلم | P37: 2026 Tasks
A38: 36 | B38: تقرير رسوم الأراضي البيضاء والشواغر وتأثير قرار الرسوم على المجموعة | C38: المالية | D38: محمد عبدالحميد | G38: مكتملة | H38: 1 | K38: =IFERROR(IF(J38="","",IF(G38="مكتملة","✓",J38-TODAY())),"تاريخ غير صحيح") | L38: =IF(G38="مكتملة","🟢 مكتملة",IF(G38="لم تبدأ","⚪ لم تبدأ",IF(J38<TODAY(),"🔴 متأخرة",IF(AND(I38<>"",J38<>"",H38<>"",((TODAY()-I38)/(J38-I38)-H38)>0.3),"🟡 تحتاج متابعة","🟢 في المسار")))) -> 🟢 مكتملة | M38: تم الرد من الإدارة المالية بانه في انتظار اصدار اللائحة لحساب الأثر | P38: 2026 Tasks
A39: 37 | B39: عقد خدمات الامن السيبراني | C39: الاستراتيجية | D39: محمد زاهر | G39: مكتملة | H39: 1 | J39: 45797 | K39: =IFERROR(IF(J39="","",IF(G39="مكتملة","✓",J39-TODAY())),"تاريخ غير صحيح") -> ✓ | L39: =IF(G39="مكتملة","🟢 مكتملة",IF(G39="لم تبدأ","⚪ لم تبدأ",IF(J39<TODAY(),"🔴 متأخرة",IF(AND(I39<>"",J39<>"",H39<>"",((TODAY()-I39)/(J39-I39)-H39)>0.3),"🟡 تحتاج متابعة","🟢 في المسار")))) -> 🟢 مكتملة | M39: مكتمل | P39: 2026 Tasks
A40: 38 | B40: تقرير تحصيل شهر 6-2025 | C40: المالية | D40: محمد خضر | G40: مكتملة | H40: 1 | J40: 45841 | K40: =IFERROR(IF(J40="","",IF(G40="مكتملة","✓",J40-TODAY())),"تاريخ غير صحيح") -> ✓ | L40: =IF(G40="مكتملة","🟢 مكتملة",IF(G40="لم تبدأ","⚪ لم تبدأ",IF(J40<TODAY(),"🔴 متأخرة",IF(AND(I40<>"",J40<>"",H40<>"",((TODAY()-I40)/(J40-I40)-H40)>0.3),"🟡 تحتاج متابعة","🟢 في المسار")))) -> 🟢 مكتملة | P40: 2026 Tasks
...

Sheet لوحة أداء الأقسام
A1: لوحة أداء الأقسام – التحليل التراكمي (2024-2026)
A2: القسم | B2: إجمالي المهام | C2: مكتملة | D2: جاري العمل | E2: لم تبدأ | F2: معدل الإنجاز | G2: متوسط الإنجاز % | H2: مهام 2026 النشطة | I2: مهام متأخرة 2026 | J2: تقييم الأداء | K2: توصية
A3: التقنية | B3: =COUNTIF('قاعدة بيانات المهام'!C:C,A3) -> 49 | C3: =COUNTIFS('قاعدة بيانات المهام'!C:C,A3,'قاعدة بيانات المهام'!G:G,"مكتملة") -> 30 | D3: =COUNTIFS('قاعدة بيانات المهام'!C:C,A3,'قاعدة بيانات المهام'!G:G,"جاري العمل") -> 19 | E3: =COUNTIFS('قاعدة بيانات المهام'!C:C,A3,'قاعدة بيانات المهام'!G:G,"لم تبدأ") -> 0 | F3: =IFERROR(C3/B3,0) -> 0.6122449 | G3: =IFERROR(AVERAGEIF('قاعدة بيانات المهام'!C:C,A3,'قاعدة بيانات المهام'!H:H),0) -> 0.96896552 | H3: =COUNTIFS('قاعدة بيانات المهام'!C:C,A3,'قاعدة بيانات المهام'!P:P,"2026 Tasks") -> 13 | I3: =COUNTIFS('قاعدة بيانات المهام'!C:C,A3,'قاعدة بيانات المهام'!P:P,"2026 Tasks",'قاعدة بيانات المهام'!G:G,"<>مكتملة",'قاعدة بيانات المهام'!J:J,"<"&TODAY(),'قاعدة بيانات المهام'!J:J,"<>") -> 1 | J3: =IF(F3>=0.75,"ممتاز 🏆",IF(F3>=0.55,"جيد ✅",IF(F3>=0.35,"متوسط ⚠️","يحتاج اهتمام 🔴"))) -> جيد ✅ | K3: مراجعة ربع سنوية
A4: المشاريع | B4: =COUNTIF('قاعدة بيانات المهام'!C:C,A4) -> 73 | C4: =COUNTIFS('قاعدة بيانات المهام'!C:C,A4,'قاعدة بيانات المهام'!G:G,"مكتملة") -> 35 | D4: =COUNTIFS('قاعدة بيانات المهام'!C:C,A4,'قاعدة بيانات المهام'!G:G,"جاري العمل") -> 38 | E4: =COUNTIFS('قاعدة بيانات المهام'!C:C,A4,'قاعدة بيانات المهام'!G:G,"لم تبدأ") -> 0 | F4: =IFERROR(C4/B4,0) -> 0.47945205 | G4: =IFERROR(AVERAGEIF('قاعدة بيانات المهام'!C:C,A4,'قاعدة بيانات المهام'!H:H),0) -> 0.9015625 | H4: =COUNTIFS('قاعدة بيانات المهام'!C:C,A4,'قاعدة بيانات المهام'!P:P,"2026 Tasks") -> 14 | I4: =COUNTIFS('قاعدة بيانات المهام'!C:C,A4,'قاعدة بيانات المهام'!P:P,"2026 Tasks",'قاعدة بيانات المهام'!G:G,"<>مكتملة",'قاعدة بيانات المهام'!J:J,"<"&TODAY(),'قاعدة بيانات المهام'!J:J,"<>") -> 2 | J4: =IF(F4>=0.75,"ممتاز 🏆",IF(F4>=0.55,"جيد ✅",IF(F4>=0.35,"متوسط ⚠️","يحتاج اهتمام 🔴"))) -> متوسط ⚠️ | K4: تدخل مباشر من الرئيس التنفيذي
A5: المالية | B5: =COUNTIF('قاعدة بيانات المهام'!C:C,A5) -> 74 | C5: =COUNTIFS('قاعدة بيانات المهام'!C:C,A5,'قاعدة بيانات المهام'!G:G,"مكتملة") -> 48 | D5: =COUNTIFS('قاعدة بيانات المهام'!C:C,A5,'قاعدة بيانات المهام'!G:G,"جاري العمل") -> 26 | E5: =COUNTIFS('قاعدة بيانات المهام'!C:C,A5,'قاعدة بيانات المهام'!G:G,"لم تبدأ") -> 0 | F5: =IFERROR(C5/B5,0) -> 0.64864865 | G5: =IFERROR(AVERAGEIF('قاعدة بيانات المهام'!C:C,A5,'قاعدة بيانات المهام'!H:H),0) -> 0.91428571 | H5: =COUNTIFS('قاعدة بيانات المهام'!C:C,A5,'قاعدة بيانات المهام'!P:P,"2026 Tasks") -> 19 | I5: =COUNTIFS('قاعدة بيانات المهام'!C:C,A5,'قاعدة بيانات المهام'!P:P,"2026 Tasks",'قاعدة بيانات المهام'!G:G,"<>مكتملة",'قاعدة بيانات المهام'!J:J,"<"&TODAY(),'قاعدة بيانات المهام'!J:J,"<>") -> 3 | J5: =IF(F5>=0.75,"ممتاز 🏆",IF(F5>=0.55,"جيد ✅",IF(F5>=0.35,"متوسط ⚠️","يحتاج اهتمام 🔴"))) -> جيد ✅ | K5: مراجعة ربع سنوية
A6: الخزينة | B6: =COUNTIF('قاعدة بيانات المهام'!C:C,A6) -> 7 | C6: =COUNTIFS('قاعدة بيانات المهام'!C:C,A6,'قاعدة بيانات المهام'!G:G,"مكتملة") -> 4 | D6: =COUNTIFS('قاعدة بيانات المهام'!C:C,A6,'قاعدة بيانات المهام'!G:G,"جاري العمل") -> 3 | E6: =COUNTIFS('قاعدة بيانات المهام'!C:C,A6,'قاعدة بيانات المهام'!G:G,"لم تبدأ") -> 0 | F6: =IFERROR(C6/B6,0) -> 0.57142857 | G6: =IFERROR(AVERAGEIF('قاعدة بيانات المهام'!C:C,A6,'قاعدة بيانات المهام'!H:H),0) -> 0.8625 | H6: =COUNTIFS('قاعدة بيانات المهام'!C:C,A6,'قاعدة بيانات المهام'!P:P,"2026 Tasks") -> 0 | I6: =COUNTIFS('قاعدة بيانات المهام'!C:C,A6,'قاعدة بيانات المهام'!P:P,"2026 Tasks",'قاعدة بيانات المهام'!G:G,"<>مكتملة",'قاعدة بيانات المهام'!J:J,"<"&TODAY(),'قاعدة بيانات المهام'!J:J,"<>") -> 0 | J6: =IF(F6>=0.75,"ممتاز 🏆",IF(F6>=0.55,"جيد ✅",IF(F6>=0.35,"متوسط ⚠️","يحتاج اهتمام 🔴"))) -> جيد ✅ | K6: مراجعة ربع سنوية
A7: الاستثمار | B7: =COUNTIF('قاعدة بيانات المهام'!C:C,A7) -> 54 | C7: =COUNTIFS('قاعدة بيانات المهام'!C:C,A7,'قاعدة بيانات المهام'!G:G,"مكتملة") -> 30 | D7: =COUNTIFS('قاعدة بيانات المهام'!C:C,A7,'قاعدة بيانات المهام'!G:G,"جاري العمل") -> 24 | E7: =COUNTIFS('قاعدة بيانات المهام'!C:C,A7,'قاعدة بيانات المهام'!G:G,"لم تبدأ") -> 0 | F7: =IFERROR(C7/B7,0) -> 0.55555556 | G7: =IFERROR(AVERAGEIF('قاعدة بيانات المهام'!C:C,A7,'قاعدة بيانات المهام'!H:H),0) -> 0.896875 | H7: =COUNTIFS('قاعدة بيانات المهام'!C:C,A7,'قاعدة بيانات المهام'!P:P,"2026 Tasks") -> 17 | I7: =COUNTIFS('قاعدة بيانات المهام'!C:C,A7,'قاعدة بيانات المهام'!P:P,"2026 Tasks",'قاعدة بيانات المهام'!G:G,"<>مكتملة",'قاعدة بيانات المهام'!J:J,"<"&TODAY(),'قاعدة بيانات المهام'!J:J,"<>") -> 3 | J7: =IF(F7>=0.75,"ممتاز 🏆",IF(F7>=0.55,"جيد ✅",IF(F7>=0.35,"متوسط ⚠️","يحتاج اهتمام 🔴"))) -> جيد ✅ | K7: خطة تحسين مطلوبة
A8: الأصول العقارية | B8: =COUNTIF('قاعدة بيانات المهام'!C:C,A8) -> 20 | C8: =COUNTIFS('قاعدة بيانات المهام'!C:C,A8,'قاعدة بيانات المهام'!G:G,"مكتملة") -> 16 | D8: =COUNTIFS('قاعدة بيانات المهام'!C:C,A8,'قاعدة بيانات المهام'!G:G,"جاري العمل") -> 4 | E8: =COUNTIFS('قاعدة بيانات المهام'!C:C,A8,'قاعدة بيانات المهام'!G:G,"لم تبدأ") -> 0 | F8: =IFERROR(C8/B8,0) -> 0.8 | G8: =IFERROR(AVERAGEIF('قاعدة بيانات المهام'!C:C,A8,'قاعدة بيانات المهام'!H:H),0) -> 0.96071429 | H8: =COUNTIFS('قاعدة بيانات المهام'!C:C,A8,'قاعدة بيانات المهام'!P:P,"2026 Tasks") -> 10 | I8: =COUNTIFS('قاعدة بيانات المهام'!C:C,A8,'قاعدة بيانات المهام'!P:P,"2026 Tasks",'قاعدة بيانات المهام'!G:G,"<>مكتملة",'قاعدة بيانات المهام'!J:J,"<"&TODAY(),'قاعدة بيانات المهام'!J:J,"<>") -> 0 | J8: =IF(F8>=0.75,"ممتاز 🏆",IF(F8>=0.55,"جيد ✅",IF(F8>=0.35,"متوسط ⚠️","يحتاج اهتمام 🔴"))) -> ممتاز 🏆 | K8: مراجعة ربع سنوية
A9: الاستراتيجية | B9: =COUNTIF('قاعدة بيانات المهام'!C:C,A9) -> 23 | C9: =COUNTIFS('قاعدة بيانات المهام'!C:C,A9,'قاعدة بيانات المهام'!G:G,"مكتملة") -> 23 | D9: =COUNTIFS('قاعدة بيانات المهام'!C:C,A9,'قاعدة بيانات المهام'!G:G,"جاري العمل") -> 0 | E9: =COUNTIFS('قاعدة بيانات المهام'!C:C,A9,'قاعدة بيانات المهام'!G:G,"لم تبدأ") -> 0 | F9: =IFERROR(C9/B9,0) -> 1 | G9: =IFERROR(AVERAGEIF('قاعدة بيانات المهام'!C:C,A9,'قاعدة بيانات المهام'!H:H),0) -> 0.98823529 | H9: =COUNTIFS('قاعدة بيانات المهام'!C:C,A9,'قاعدة بيانات المهام'!P:P,"2026 Tasks") -> 8 | I9: =COUNTIFS('قاعدة بيانات المهام'!C:C,A9,'قاعدة بيانات المهام'!P:P,"2026 Tasks",'قاعدة بيانات المهام'!G:G,"<>مكتملة",'قاعدة بيانات المهام'!J:J,"<"&TODAY(),'قاعدة بيانات المهام'!J:J,"<>") -> 0 | J9: =IF(F9>=0.75,"ممتاز 🏆",IF(F9>=0.55,"جيد ✅",IF(F9>=0.35,"متوسط ⚠️","يحتاج اهتمام 🔴"))) -> ممتاز 🏆 | K9: حافظ على الزخم
A10: الموارد البشرية | B10: =COUNTIF('قاعدة بيانات المهام'!C:C,A10) -> 19 | C10: =COUNTIFS('قاعدة بيانات المهام'!C:C,A10,'قاعدة بيانات المهام'!G:G,"مكتملة") -> 6 | D10: =COUNTIFS('قاعدة بيانات المهام'!C:C,A10,'قاعدة بيانات المهام'!G:G,"جاري العمل") -> 13 | E10: =COUNTIFS('قاعدة بيانات المهام'!C:C,A10,'قاعدة بيانات المهام'!G:G,"لم تبدأ") -> 0 | F10: =IFERROR(C10/B10,0) -> 0.31578947 | G10: =IFERROR(AVERAGEIF('قاعدة بيانات المهام'!C:C,A10,'قاعدة بيانات المهام'!H:H),0) -> 0.75384615 | H10: =COUNTIFS('قاعدة بيانات المهام'!C:C,A10,'قاعدة بيانات المهام'!P:P,"2026 Tasks") -> 2 | I10: =COUNTIFS('قاعدة بيانات المهام'!C:C,A10,'قاعدة بيانات المهام'!P:P,"2026 Tasks",'قاعدة بيانات المهام'!G:G,"<>مكتملة",'قاعدة بيانات المهام'!J:J,"<"&TODAY(),'قاعدة بيانات المهام'!J:J,"<>") -> 1 | J10: =IF(F10>=0.75,"ممتاز 🏆",IF(F10>=0.55,"جيد ✅",IF(F10>=0.35,"متوسط ⚠️","يحتاج اهتمام 🔴"))) -> يحتاج اهتمام 🔴 | K10: تدخل مباشر من الرئيس التنفيذي
A11: الادارة القانونية | B11: =COUNTIF('قاعدة بيانات المهام'!C:C,A11) -> 36 | C11: =COUNTIFS('قاعدة بيانات المهام'!C:C,A11,'قاعدة بيانات المهام'!G:G,"مكتملة") -> 24 | D11: =COUNTIFS('قاعدة بيانات المهام'!C:C,A11,'قاعدة بيانات المهام'!G:G,"جاري العمل") -> 12 | E11: =COUNTIFS('قاعدة بيانات المهام'!C:C,A11,'قاعدة بيانات المهام'!G:G,"لم تبدأ") -> 0 | F11: =IFERROR(C11/B11,0) -> 0.66666667 | G11: =IFERROR(AVERAGEIF('قاعدة بيانات المهام'!C:C,A11,'قاعدة بيانات المهام'!H:H),0) -> 0.82619048 | H11: =COUNTIFS('قاعدة بيانات المهام'!C:C,A11,'قاعدة بيانات المهام'!P:P,"2026 Tasks") -> 7 | I11: =COUNTIFS('قاعدة بيانات المهام'!C:C,A11,'قاعدة بيانات المهام'!P:P,"2026 Tasks",'قاعدة بيانات المهام'!G:G,"<>مكتملة",'قاعدة بيانات المهام'!J:J,"<"&TODAY(),'قاعدة بيانات المهام'!J:J,"<>") -> 0 | J11: =IF(F11>=0.75,"ممتاز 🏆",IF(F11>=0.55,"جيد ✅",IF(F11>=0.35,"متوسط ⚠️","يحتاج اهتمام 🔴"))) -> جيد ✅ | K11: خطة تحسين مطلوبة
A12: المراجعة | B12: =COUNTIF('قاعدة بيانات المهام'!C:C,A12) -> 6 | C12: =COUNTIFS('قاعدة بيانات المهام'!C:C,A12,'قاعدة بيانات المهام'!G:G,"مكتملة") -> 2 | D12: =COUNTIFS('قاعدة بيانات المهام'!C:C,A12,'قاعدة بيانات المهام'!G:G,"جاري العمل") -> 4 | E12: =COUNTIFS('قاعدة بيانات المهام'!C:C,A12,'قاعدة بيانات المهام'!G:G,"لم تبدأ") -> 0 | F12: =IFERROR(C12/B12,0) -> 0.33333333 | G12: =IFERROR(AVERAGEIF('قاعدة بيانات المهام'!C:C,A12,'قاعدة بيانات المهام'!H:H),0) -> 1 | H12: =COUNTIFS('قاعدة بيانات المهام'!C:C,A12,'قاعدة بيانات المهام'!P:P,"2026 Tasks") -> 0 | I12: =COUNTIFS('قاعدة بيانات المهام'!C:C,A12,'قاعدة بيانات المهام'!P:P,"2026 Tasks",'قاعدة بيانات المهام'!G:G,"<>مكتملة",'قاعدة بيانات المهام'!J:J,"<"&TODAY(),'قاعدة بيانات المهام'!J:J,"<>") -> 0 | J12: =IF(F12>=0.75,"ممتاز 🏆",IF(F12>=0.55,"جيد ✅",IF(F12>=0.35,"متوسط ⚠️","يحتاج اهتمام 🔴"))) -> يحتاج اهتمام 🔴 | K12: تدخل مباشر من الرئيس التنفيذي
A13: المدير العام | B13: =COUNTIF('قاعدة بيانات المهام'!C:C,A13) -> 20 | C13: =COUNTIFS('قاعدة بيانات المهام'!C:C,A13,'قاعدة بيانات المهام'!G:G,"مكتملة") -> 7 | D13: =COUNTIFS('قاعدة بيانات المهام'!C:C,A13,'قاعدة بيانات المهام'!G:G,"جاري العمل") -> 13 | E13: =COUNTIFS('قاعدة بيانات المهام'!C:C,A13,'قاعدة بيانات المهام'!G:G,"لم تبدأ") -> 0 | F13: =IFERROR(C13/B13,0) -> 0.35 | G13: =IFERROR(AVERAGEIF('قاعدة بيانات المهام'!C:C,A13,'قاعدة بيانات المهام'!H:H),0) -> 0.70714286 | H13: =COUNTIFS('قاعدة بيانات المهام'!C:C,A13,'قاعدة بيانات المهام'!P:P,"2026 Tasks") -> 0 | I13: =COUNTIFS('قاعدة بيانات المهام'!C:C,A13,'قاعدة بيانات المهام'!P:P,"2026 Tasks",'قاعدة بيانات المهام'!G:G,"<>مكتملة",'قاعدة بيانات المهام'!J:J,"<"&TODAY(),'قاعدة بيانات المهام'!J:J,"<>") -> 0 | J13: =IF(F13>=0.75,"ممتاز 🏆",IF(F13>=0.55,"جيد ✅",IF(F13>=0.35,"متوسط ⚠️","يحتاج اهتمام 🔴"))) -> متوسط ⚠️ | K13: تدخل مباشر من الرئيس التنفيذي
A14: الرئيس التنفيذي | B14: =COUNTIF('قاعدة بيانات المهام'!C:C,A14) -> 4 | C14: =COUNTIFS('قاعدة بيانات المهام'!C:C,A14,'قاعدة بيانات المهام'!G:G,"مكتملة") -> 1 | D14: =COUNTIFS('قاعدة بيانات المهام'!C:C,A14,'قاعدة بيانات المهام'!G:G,"جاري العمل") -> 3 | E14: =COUNTIFS('قاعدة بيانات المهام'!C:C,A14,'قاعدة بيانات المهام'!G:G,"لم تبدأ") -> 0 | F14: =IFERROR(C14/B14,0) -> 0.25 | G14: =IFERROR(AVERAGEIF('قاعدة بيانات المهام'!C:C,A14,'قاعدة بيانات المهام'!H:H),0) -> 0.975 | H14: =COUNTIFS('قاعدة بيانات المهام'!C:C,A14,'قاعدة بيانات المهام'!P:P,"2026 Tasks") -> 1 | I14: =COUNTIFS('قاعدة بيانات المهام'!C:C,A14,'قاعدة بيانات المهام'!P:P,"2026 Tasks",'قاعدة بيانات المهام'!G:G,"<>مكتملة",'قاعدة بيانات المهام'!J:J,"<"&TODAY(),'قاعدة بيانات المهام'!J:J,"<>") -> 0 | J14: =IF(F14>=0.75,"ممتاز 🏆",IF(F14>=0.55,"جيد ✅",IF(F14>=0.35,"متوسط ⚠️","يحتاج اهتمام 🔴"))) -> يحتاج اهتمام 🔴 | K14: تدخل مباشر من الرئيس التنفيذي
... A18: التجارة | B18: =COUNTIF('قاعدة بيانات المهام'!C:C,A18) -> 7 | C18: =COUNTIFS('قاعدة بيانات المهام'!C:C,A18,'قاعدة بيانات المهام'!G:G,"مكتملة") -> 7 | D18: =COUNTIFS('قاعدة بيانات المهام'!C:C,A18,'قاعدة بيانات المهام'!G:G,"جاري العمل") -> 0 | E18: =COUNTIFS('قاعدة بيانات المهام'!C:C,A18,'قاعدة بيانات المهام'!G:G,"لم تبدأ") -> 0 | F18: =IFERROR(C18/B18,0) -> 1 | G18: =IFERROR(AVERAGEIF('قاعدة بيانات المهام'!C:C,A18,'قاعدة بيانات المهام'!H:H),0) -> 1 | H18: =COUNTIFS('قاعدة بيانات المهام'!C:C,A18,'قاعدة بيانات المهام'!P:P,"2026 Tasks") -> 0 | I18: =COUNTIFS('قاعدة بيانات المهام'!C:C,A18,'قاعدة بيانات المهام'!P:P,"2026 Tasks",'قاعدة بيانات المهام'!G:G,"<>مكتملة",'قاعدة بيانات المهام'!J:J,"<"&TODAY(),'قاعدة بيانات المهام'!J:J,"<>") -> 0 | J18: =IF(F18>=0.75,"ممتاز 🏆",IF(F18>=0.55,"جيد ✅",IF(F18>=0.35,"متوسط ⚠️","يحتاج اهتمام 🔴"))) -> ممتاز 🏆 | K18: حافظ على الزخم
A19: المجموع الكلي | B19: =SUM(B3:B18) -> 411 | C19: =SUM(C3:C18) -> 243 | D19: =SUM(D3:D18) -> 168 | E19: =SUM(E3:E18) -> 0 | F19: =IFERROR(C19/B19,0) -> 0.59124088 | G19: =IFERROR(AVERAGE(G3:G18),0) -> 0.83481153 | H19: =SUM(H3:H18) -> 92 | I19: =SUM(I3:I18) -> 10

Sheet دليل الاستخدام
A1: دليل استخدام قاعدة البيانات المطورة
A3: 📋 هيكل الملف
A4: قاعدة بيانات المهام | B4: جميع المهام التاريخية 2024-2026 في جدول واحد (428 صف)
A5: المهام النشطة 2026 | B5: المهام الحالية فقط (94 مهمة) – للمتابعة اليومية
A6: لوحة أداء الأقسام | B6: تحليل أداء كل قسم تراكمياً
A7: دليل الاستخدام | B7: هذه الصفحة
A9: 🎯 أعمدة يجب ملؤها
A10: الأولوية (E) | B10: اختر من القائمة: P1 عاجل / P2 مهم / P3 عادي
A11: الركيزة الاستراتيجية (F) | B11: اختر من القائمة: نمو الإيرادات / الامتثال والمخاطر / التميز التشغيلي / التحول الرقمي / الكفاءات والأفراد
A12: نسبة الإنجاز (H) | B12: أدخل رقماً من 0 إلى 100% (مثال: 75%)
A14: 🚦 مؤشر المخاطر – القراءة
A15: 🟢 في المسار | B15: المهمة تسير حسب الخطة – لا تدخل مطلوب
A16: 🟡 تحتاج متابعة | B16: الإنجاز متأخر عن الوقت بـ 30%+ – يجب المراجعة
A17: 🔴 متأخرة | B17: تجاوزت تاريخ الانتهاء ولم تكتمل – تدخل عاجل
A18: ⚪ لم تبدأ | B18: المهمة لم تبدأ بعد
A19: 🟢 مكتملة | B19: اكتملت المهمة
A21: 🔍 نصائح الاستخدام
A22: الفلترة | B22: استخدم Auto Filter على أي عمود للتصفية حسب القسم أو الموظف أو الحالة
A23: البحث عن متأخرة | B23: فلتر عمود L على '🔴 متأخرة' لرؤية كل المهام المتأخرة فوراً
A24: تحديث أسبوعي | B24: حدّث نسبة الإنجاز والحالة كل أسبوع – المؤشرات تتحدث تلقائياً
A25: الأولوية أولاً | B25: ابدأ اجتماع المتابعة بفلترة P1 + 🔴 لتحديد أهم القرارات
